Workbook
Name VeteranMVPTeams: #REF!
Name ProspectGPMin: Variables!$D$15
Name ProspectMVPTeams: #REF!
Name RivalGPMin: Variables!$D$13
Name ContenderGPMin: Variables!$D$16
Name VeteranGPMin: Variables!$D$12
Name AmateurMVPTeams: #REF!
Name ChallengerGPMin: Variables!$D$14
Name PremierMVPTeams: #REF!
Name EliteGPMin: Variables!$D$11
Name AmateurGPMin: Variables!$D$17
Name PremierGPMin: Variables!$D$9
Name MasterMVPTeams: #REF!
Name MasterGPMin: Variables!$D$10
Name ChallengerMVPTeams: #REF!
Name ContenderMVPTeams: #REF!
Name EliteMVPTeams: #REF!
Name RivalMVPTeams: #REF!

Sheet Glossary
A1: Abbreviation | B1: Name | C1: Formula/Explanation | D1: Link
A2: Player | B2: Player
A3: Tier | B3: Tier
A4: Team(s) | B4: Team(s) | C4: All teams the player has played for in the tier (ordered from most recent (at the top) to least recent (at the bottom)).
A5: Franchise(s) | B5: Franchise(s) | C5: All franchises the player has played for in the tier (ordered from most recent (at the top) to least recent (at the bottom)).
A6: Conference | B6: Conference | C6: The conference the player has played the most in.
A7: RPV | B7: RSC Performance Value | C7: Average of SBV and IDR. Equal weight is given to both values
A8: SBV | B8: Stats-Based Value | C8: Standardize (Z-Score) NP/A, G/A, A/A, Sv/A, and S/A, then weighted-average them together, with their correlation to PWE serving as the weights. | D8: S23 RSC SBV
A9: IDR | B9: Index Derived Rating | C9: Take the player's Indexes (defined below), and their raw per game stats, and multiply them by the average of their correlation to win% and PWE, sum the weighted indexes, then find what standard deviation the player's value is at. Multiply that value by 25 and add 50, to make the scale more intuitive. An average player will have an IDR of around 50, and each standard deviation the player's score falls further away from average will be a 25 point increase or decrease. IDR was designed to factor in stats against, as well as strength of schedule. By also measuring your performance as ratios instead of just as raw per game stats you are not freely rewarded for getting 400 points against a team that normally gives up 400 points, and you aren't hurt for getting 150 points against a team that normally only gives up that many. It keeps track of both offensive and defensive stats, so what you let your opponents do is now also an important factor. you can't just ball chase your way to a high IDR in the same way that you can a high SBV. | D9: RSC S23 IDR
A10: GP | B10: Games Played | C10: W + L
A11: W | B11: Wins
A12: L | B12: Losses
A13: Win % | B13: Win Percentage | C13: W / GP
A14: MVPs | B14: Most Valuable Players | C14: Amount of times game MVP
A15: Pts | B15: Points
A16: PPG | B16: Points per Game
A17: Goals | B17: Goals
A18: GPG | B18: Goals per Game
A19: Assists | B19: Assists
A20: APG | B20: Assists per Game
A21: Saves | B21: Saves
A22: SvPG | B22: Saves per Game
A23: Shots | B23: Shots
A24: Shot % | B24: Shot Percentage | C24: Shot Percentage
A25: DI | B25: Demos Inflicted | C25: Number of times you murder an oppponent
A26: DT | B26: Demos Taken | C26: Number of times you are slain by the opposition

Sheet Sorted RPV
A1: Sort By | B1: All
A2: Sort By | B2: RPV
A3: Smaller = Better? | B3: FALSE
A5: {='Aggregate RPV'!A1} -> Tier | B5: RSC ID | C5: Name | D5: Team | E5: Conference | F5: SBV | G5: IDR | H5: RPV | I5: GP | J5: W | K5: L | L5: Win% | M5: MVPs | N5: Pts | O5: Goals | P5: Assists | Q5: Saves | R5: Shots | S5: Shot % | T5: PPG | U5: GPG | V5: APG | W5: SvPG | X5: ShPG | Y5: Cycles | Z5: Hat Tricks | AA5: Playmakers | AB5: Saviors | AC5: DI | AD5: DT
A6: =IFERROR(__xludf.DUMMYFUNCTION("SORT(FILTER({'Aggregate RPV'!A2:A3286,'Aggregate RPV'!B2:C3286,'Aggregate RPV'!D2:F3286,'Aggregate RPV'!H2:J3286},IF(B1=""All"",'Aggregate RPV'!B2:B3286<>"""",'Aggregate RPV'!A2:A3286=B1)),1,1,MATCH(B2,5:5,0),B3)"),"Amateur") -> Amateur | B6: =IFERROR(__xludf.DUMMYFUNCTION("""COMPUTED_VALUE"""),"RSC008201") -> RSC008201 | C6: =IFERROR(__xludf.DUMMYFUNCTION("""COMPUTED_VALUE"""),"CatalystNEMO") -> CatalystNEMO | D6: =IFERROR(__xludf.DUMMYFUNCTION("""COMPUTED_VALUE"""),"Bombers") -> Bombers | E6: =IFERROR(__xludf.DUMMYFUNCTION("""COMPUTED_VALUE"""),"N/A") -> N/A | F6: =IFERROR(__xludf.DUMMYFUNCTION("""COMPUTED_VALUE"""),152.0636508596478) -> 152.06365 | G6: =IFERROR(__xludf.DUMMYFUNCTION("""COMPUTED_VALUE"""),126.93443064018042) -> 126.93443 | H6: =IFERROR(__xludf.DUMMYFUNCTION("""COMPUTED_VALUE"""),139.49904074991412) -> 139.49904 | I6: =IFERROR(__xludf.DUMMYFUNCTION("""COMPUTED_VALUE"""),4.0) -> 4 | J6: =IFERROR(__xludf.DUMMYFUNCTION("IFERROR(FILTER(Stats!$F:$Z,(Stats!$A:$A=$A6)*(Stats!$B:$B=$B6)))"),3.0) -> 3 | K6: =IFERROR(__xludf.DUMMYFUNCTION("""COMPUTED_VALUE"""),1.0) -> 1 | L6: =IFERROR(__xludf.DUMMYFUNCTION("""COMPUTED_VALUE"""),0.75) -> 0.75 | M6: =IFERROR(__xludf.DUMMYFUNCTION("""COMPUTED_VALUE"""),2.0) -> 2 | N6: =IFERROR(__xludf.DUMMYFUNCTION("""COMPUTED_VALUE"""),1760.0) -> 1760 | O6: =IFERROR(__xludf.DUMMYFUNCTION("""COMPUTED_VALUE"""),6.0) -> 6 | P6: =IFERROR(__xludf.DUMMYFUNCTION("""COMPUTED_VALUE"""),5.0) -> 5 | Q6: =IFERROR(__xludf.DUMMYFUNCTION("""COMPUTED_VALUE"""),3.0) -> 3 | R6: =IFERROR(__xludf.DUMMYFUNCTION("""COMPUTED_VALUE"""),16.0) -> 16 | S6: =IFERROR(__xludf.DUMMYFUNCTION("""COMPUTED_VALUE"""),0.375) -> 0.375 | T6: =IFERROR(__xludf.DUMMYFUNCTION("""COMPUTED_VALUE"""),440.0) -> 440 | U6: =IFERROR(__xludf.DUMMYFUNCTION("""COMPUTED_VALUE"""),1.5) -> 1.5 | V6: =IFERROR(__xludf.DUMMYFUNCTION("""COMPUTED_VALUE"""),1.25) -> 1.25 | W6: =IFERROR(__xludf.DUMMYFUNCTION("""COMPUTED_VALUE"""),0.75) -> 0.75 | X6: =IFERROR(__xludf.DUMMYFUNCTION("""COMPUTED_VALUE"""),4.0) -> 4 | Y6: =IFERROR(__xludf.DUMMYFUNCTION("""COMPUTED_VALUE"""),2.0) -> 2 | Z6: =IFERROR(__xludf.DUMMYFUNCTION("""COMPUTED_VALUE"""),0.0) -> 0 | AA6: =IFERROR(__xludf.DUMMYFUNCTION("""COMPUTED_VALUE"""),0.0) -> 0 | AB6: =IFERROR(__xludf.DUMMYFUNCTION("""COMPUTED_VALUE"""),0.0) -> 0 | AC6: =IFERROR(__xludf.DUMMYFUNCTION("""COMPUTED_VALUE"""),2.0) -> 2 | AD6: =IFERROR(__xludf.DUMMYFUNCTION("""COMPUTED_VALUE"""),5.0) -> 5
A7: =IFERROR(__xludf.DUMMYFUNCTION("""COMPUTED_VALUE"""),"Amateur") -> Amateur | B7: =IFERROR(__xludf.DUMMYFUNCTION("""COMPUTED_VALUE"""),"RSC008541") -> RSC008541 | C7: =IFERROR(__xludf.DUMMYFUNCTION("""COMPUTED_VALUE"""),"Jito1017") -> Jito1017 | D7: =IFERROR(__xludf.DUMMYFUNCTION("""COMPUTED_VALUE"""),"Electric Eels Winter Fresh Garlic Knots") -> Electric Eels Winter Fresh Garlic Knots | E7: =IFERROR(__xludf.DUMMYFUNCTION("""COMPUTED_VALUE"""),"N/A N/A N/A") -> N/A N/A N/A | F7: =IFERROR(__xludf.DUMMYFUNCTION("""COMPUTED_VALUE"""),131.21159464877658) -> 131.21159 | G7: =IFERROR(__xludf.DUMMYFUNCTION("""COMPUTED_VALUE"""),98.55238766449756) -> 98.552388 | H7: =IFERROR(__xludf.DUMMYFUNCTION("""COMPUTED_VALUE"""),114.88199115663707) -> 114.88199 | I7: =IFERROR(__xludf.DUMMYFUNCTION("""COMPUTED_VALUE"""),16.0) -> 16 | J7: =IFERROR(__xludf.DUMMYFUNCTION("IFERROR(FILTER(Stats!$F:$Z,(Stats!$A:$A=$A7)*(Stats!$B:$B=$B7)))"),12.0) -> 12 | K7: =IFERROR(__xludf.DUMMYFUNCTION("""COMPUTED_VALUE"""),4.0) -> 4 | L7: =IFERROR(__xludf.DUMMYFUNCTION("""COMPUTED_VALUE"""),0.75) -> 0.75 | M7: =IFERROR(__xludf.DUMMYFUNCTION("""COMPUTED_VALUE"""),8.0) -> 8 | N7: =IFERROR(__xludf.DUMMYFUNCTION("""COMPUTED_VALUE"""),7003.0) -> 7003 | O7: =IFERROR(__xludf.DUMMYFUNCTION("""COMPUTED_VALUE"""),23.0) -> 23 | P7: =IFERROR(__xludf.DUMMYFUNCTION("""COMPUTED_VALUE"""),14.0) -> 14 | Q7: =IFERROR(__xludf.DUMMYFUNCTION("""COMPUTED_VALUE"""),13.0) -> 13 | R7: =IFERROR(__xludf.DUMMYFUNCTION("""COMPUTED_VALUE"""),51.0) -> 51 | S7: =IFERROR(__xludf.DUMMYFUNCTION("""COMPUTED_VALUE"""),0.45098039215686275) -> 0.45098039 | T7: =IFERROR(__xludf.DUMMYFUNCTION("""COMPUTED_VALUE"""),437.6875) -> 437.6875 | U7: =IFERROR(__xludf.DUMMYFUNCTION("""COMPUTED_VALUE"""),1.4375) -> 1.4375 | V7: =IFERROR(__xludf.DUMMYFUNCTION("""COMPUTED_VALUE"""),0.875) -> 0.875 | W7: =IFERROR(__xludf.DUMMYFUNCTION("""COMPUTED_VALUE"""),0.8125) -> 0.8125 | X7: =IFERROR(__xludf.DUMMYFUNCTION("""COMPUTED_VALUE"""),3.1875) -> 3.1875 | Y7: =IFERROR(__xludf.DUMMYFUNCTION("""COMPUTED_VALUE"""),6.0) -> 6 | Z7: =IFERROR(__xludf.DUMMYFUNCTION("""COMPUTED_VALUE"""),3.0) -> 3 | AA7: =IFERROR(__xludf.DUMMYFUNCTION("""COMPUTED_VALUE"""),0.0) -> 0 | AB7: =IFERROR(__xludf.DUMMYFUNCTION("""COMPUTED_VALUE"""),0.0) -> 0 | AC7: =IFERROR(__xludf.DUMMYFUNCTION("""COMPUTED_VALUE"""),14.0) -> 14 | AD7: =IFERROR(__xludf.DUMMYFUNCTION("""COMPUTED_VALUE"""),15.0) -> 15
A8: =IFERROR(__xludf.DUMMYFUNCTION("""COMPUTED_VALUE"""),"Amateur") -> Amateur | B8: =IFERROR(__xludf.DUMMYFUNCTION("""COMPUTED_VALUE"""),"RSC008178") -> RSC008178 | C8: =IFERROR(__xludf.DUMMYFUNCTION("""COMPUTED_VALUE"""),"Bigwigglystylezz") -> Bigwigglystylezz | D8: =IFERROR(__xludf.DUMMYFUNCTION("""COMPUTED_VALUE"""),"Winter Fresh") -> Winter Fresh | E8: =IFERROR(__xludf.DUMMYFUNCTION("""COMPUTED_VALUE"""),"N/A") -> N/A | F8: =IFERROR(__xludf.DUMMYFUNCTION("""COMPUTED_VALUE"""),81.69571187198164) -> 81.695712 | G8: =IFERROR(__xludf.DUMMYFUNCTION("""COMPUTED_VALUE"""),73.67911949155078) -> 73.679119 | H8: =IFERROR(__xludf.DUMMYFUNCTION("""COMPUTED_VALUE"""),77.68741568176621) -> 77.687416 | I8: =IFERROR(__xludf.DUMMYFUNCTION("""COMPUTED_VALUE"""),43.0) -> 43 | J8: =IFERROR(__xludf.DUMMYFUNCTION("IFERROR(FILTER(Stats!$F:$Z,(Stats!$A:$A=$A8)*(Stats!$B:$B=$B8)))"),26.0) -> 26 | K8: =IFERROR(__xludf.DUMMYFUNCTION("""COMPUTED_VALUE"""),17.0) -> 17 | L8: =IFERROR(__xludf.DUMMYFUNCTION("""COMPUTED_VALUE"""),0.6046511627906976) -> 0.60465116 | M8: =IFERROR(__xludf.DUMMYFUNCTION("""COMPUTED_VALUE"""),13.0) -> 13 | N8: =IFERROR(__xludf.DUMMYFUNCTION("""COMPUTED_VALUE"""),15291.0) -> 15291 | O8: =IFERROR(__xludf.DUMMYFUNCTION("""COMPUTED_VALUE"""),48.0) -> 48 | P8: =IFERROR(__xludf.DUMMYFUNCTION("""COMPUTED_VALUE"""),23.0) -> 23 | Q8: =IFERROR(__xludf.DUMMYFUNCTION("""COMPUTED_VALUE"""),37.0) -> 37 | R8: =IFERROR(__xludf.DUMMYFUNCTION("""COMPUTED_VALUE"""),112.0) -> 112 | S8: =IFERROR(__xludf.DUMMYFUNCTION("""COMPUTED_VALUE"""),0.42857142857142855) -> 0.42857143 | T8: =IFERROR(__xludf.DUMMYFUNCTION("""COMPUTED_VALUE"""),355.6046511627907) -> 355.60465 | U8: =IFERROR(__xludf.DUMMYFUNCTION("""COMPUTED_VALUE"""),1.1162790697674418) -> 1.1162791 | V8: =IFERROR(__xludf.DUMMYFUNCTION("""COMPUTED_VALUE"""),0.5348837209302325) -> 0.53488372 | W8: =IFERROR(__xludf.DUMMYFUNCTION("""COMPUTED_VALUE"""),0.8604651162790697) -> 0.86046512 | X8: =IFERROR(__xludf.DUMMYFUNCTION("""COMPUTED_VALUE"""),2.604651162790698) -> 2.6046512 | Y8: =IFERROR(__xludf.DUMMYFUNCTION("""COMPUTED_VALUE"""),6.0) -> 6 | Z8: =IFERROR(__xludf.DUMMYFUNCTION("""COMPUTED_VALUE"""),4.0) -> 4 | AA8: =IFERROR(__xludf.DUMMYFUNCTION("""COMPUTED_VALUE"""),3.0) -> 3 | AB8: =IFERROR(__xludf.DUMMYFUNCTION("""COMPUTED_VALUE"""),0.0) -> 0 | AC8: =IFERROR(__xludf.DUMMYFUNCTION("""COMPUTED_VALUE"""),30.0) -> 30 | AD8: =IFERROR(__xludf.DUMMYFUNCTION("""COMPUTED_VALUE"""),24.0) -> 24
A9: =IFERROR(__xludf.DUMMYFUNCTION("""COMPUTED_VALUE"""),"Amateur") -> Amateur | B9: =IFERROR(__xludf.DUMMYFUNCTION("""COMPUTED_VALUE"""),"RSC007468") -> RSC007468 | C9: =IFERROR(__xludf.DUMMYFUNCTION("""COMPUTED_VALUE"""),"im_link42") -> im_link42 | D9: =IFERROR(__xludf.DUMMYFUNCTION("""COMPUTED_VALUE"""),"Kappa") -> Kappa | E9: =IFERROR(__xludf.DUMMYFUNCTION("""COMPUTED_VALUE"""),"N/A") -> N/A | F9: =IFERROR(__xludf.DUMMYFUNCTION("""COMPUTED_VALUE"""),80.84796465516943) -> 80.847965 | G9: =IFERROR(__xludf.DUMMYFUNCTION("""COMPUTED_VALUE"""),67.6451175197777) -> 67.645118 | H9: =IFERROR(__xludf.DUMMYFUNCTION("""COMPUTED_VALUE"""),74.24654108747356) -> 74.246541 | I9: =IFERROR(__xludf.DUMMYFUNCTION("""COMPUTED_VALUE"""),46.0) -> 46 | J9: =IFERROR(__xludf.DUMMYFUNCTION("IFERROR(FILTER(Stats!$F:$Z,(Stats!$A:$A=$A9)*(Stats!$B:$B=$B9)))"),20.0) -> 20 | K9: =IFERROR(__xludf.DUMMYFUNCTION("""COMPUTED_VALUE"""),26.0) -> 26 | L9: =IFERROR(__xludf.DUMMYFUNCTION("""COMPUTED_VALUE"""),0.43478260869565216) -> 0.43478261 | M9: =IFERROR(__xludf.DUMMYFUNCTION("""COMPUTED_VALUE"""),14.0) -> 14 | N9: =IFERROR(__xludf.DUMMYFUNCTION("""COMPUTED_VALUE"""),17796.0) -> 17796 | O9: =IFERROR(__xludf.DUMMYFUNCTION("""COMPUTED_VALUE"""),46.0) -> 46 | P9: =IFERROR(__xludf.DUMMYFUNCTION("""COMPUTED_VALUE"""),20.0) -> 20 | Q9: =IFERROR(__xludf.DUMMYFUNCTION("""COMPUTED_VALUE"""),74.0) -> 74 | R9: =IFERROR(__xludf.DUMMYFUNCTION("""COMPUTED_VALUE"""),126.0) -> 126 | S9: =IFERROR(__xludf.DUMMYFUNCTION("""COMPUTED_VALUE"""),0.36507936507936506) -> 0.36507937 | T9: =IFERROR(__xludf.DUMMYFUNCTION("""COMPUTED_VALUE"""),386.8695652173913) -> 386.86957 | U9: =IFERROR(__xludf.DUMMYFUNCTION("""COMPUTED_VALUE"""),1.0) -> 1 | V9: =IFERROR(__xludf.DUMMYFUNCTION("""COMPUTED_VALUE"""),0.43478260869565216) -> 0.43478261 | W9: =IFERROR(__xludf.DUMMYFUNCTION("""COMPUTED_VALUE"""),1.608695652173913) -> 1.6086957 | X9: =IFERROR(__xludf.DUMMYFUNCTION("""COMPUTED_VALUE"""),2.739130434782609) -> 2.7391304 | Y9: =IFERROR(__xludf.DUMMYFUNCTION("""COMPUTED_VALUE"""),12.0) -> 12 | Z9: =IFERROR(__xludf.DUMMYFUNCTION("""COMPUTED_VALUE"""),2.0) -> 2 | AA9: =IFERROR(__xludf.DUMMYFUNCTION("""COMPUTED_VALUE"""),0.0) -> 0 | AB9: =IFERROR(__xludf.DUMMYFUNCTION("""COMPUTED_VALUE"""),7.0) -> 7 | AC9: =IFERROR(__xludf.DUMMYFUNCTION("""COMPUTED_VALUE"""),25.0) -> 25 | AD9: =IFERROR(__xludf.DUMMYFUNCTION("""COMPUTED_VALUE"""),34.0) -> 34
A10: =IFERROR(__xludf.DUMMYFUNCTION("""COMPUTED_VALUE"""),"Amateur") -> Amateur | B10: =IFERROR(__xludf.DUMMYFUNCTION("""COMPUTED_VALUE"""),"RSC007621") -> RSC007621 | C10: =IFERROR(__xludf.DUMMYFUNCTION("""COMPUTED_VALUE"""),"Classy-God57") -> Classy-God57 | D10: =IFERROR(__xludf.DUMMYFUNCTION("""COMPUTED_VALUE"""),"Winter Fresh") -> Winter Fresh | E10: =IFERROR(__xludf.DUMMYFUNCTION("""COMPUTED_VALUE"""),"N/A") -> N/A | F10: =IFERROR(__xludf.DUMMYFUNCTION("""COMPUTED_VALUE"""),75.87398555719933) -> 75.873986 | G10: =IFERROR(__xludf.DUMMYFUNCTION("""COMPUTED_VALUE"""),71.38544653711753) -> 71.385447 | H10: =IFERROR(__xludf.DUMMYFUNCTION("""COMPUTED_VALUE"""),73.62971604715844) -> 73.629716 | I10: =IFERROR(__xludf.DUMMYFUNCTION("""COMPUTED_VALUE"""),47.0) -> 47 | J10: =IFERROR(__xludf.DUMMYFUNCTION("IFERROR(FILTER(Stats!$F:$Z,(Stats!$A:$A=$A10)*(Stats!$B:$B=$B10)))"),30.0) -> 30 | K10: =IFERROR(__xludf.DUMMYFUNCTION("""COMPUTED_VALUE"""),17.0) -> 17 | L10: =IFERROR(__xludf.DUMMYFUNCTION("""COMPUTED_VALUE"""),0.6382978723404256) -> 0.63829787 | M10: =IFERROR(__xludf.DUMMYFUNCTION("""COMPUTED_VALUE"""),6.0) -> 6 | N10: =IFERROR(__xludf.DUMMYFUNCTION("""COMPUTED_VALUE"""),15486.0) -> 15486 | O10: =IFERROR(__xludf.DUMMYFUNCTION("""COMPUTED_VALUE"""),43.0) -> 43 | P10: =IFERROR(__xludf.DUMMYFUNCTION("""COMPUTED_VALUE"""),27.0) -> 27 | Q10: =IFERROR(__xludf.DUMMYFUNCTION("""COMPUTED_VALUE"""),41.0) -> 41 | R10: =IFERROR(__xludf.DUMMYFUNCTION("""COMPUTED_VALUE"""),139.0) -> 139 | S10: =IFERROR(__xludf.DUMMYFUNCTION("""COMPUTED_VALUE"""),0.30935251798561153) -> 0.30935252 | T10: =IFERROR(__xludf.DUMMYFUNCTION("""COMPUTED_VALUE"""),329.48936170212767) -> 329.48936 | U10: =IFERROR(__xludf.DUMMYFUNCTION("""COMPUTED_VALUE"""),0.9148936170212766) -> 0.91489362 | V10: =IFERROR(__xludf.DUMMYFUNCTION("""COMPUTED_VALUE"""),0.574468085106383) -> 0.57446809 | W10: =IFERROR(__xludf.DUMMYFUNCTION("""COMPUTED_VALUE"""),0.8723404255319149) -> 0.87234043 | X10: =IFERROR(__xludf.DUMMYFUNCTION("""COMPUTED_VALUE"""),2.9574468085106385) -> 2.9574468 | Y10: =IFERROR(__xludf.DUMMYFUNCTION("""COMPUTED_VALUE"""),6.0) -> 6 | Z10: =IFERROR(__xludf.DUMMYFUNCTION("""COMPUTED_VALUE"""),2.0) -> 2 | AA10: =IFERROR(__xludf.DUMMYFUNCTION("""COMPUTED_VALUE"""),0.0) -> 0 | AB10: =IFERROR(__xludf.DUMMYFUNCTION("""COMPUTED_VALUE"""),3.0) -> 3 | AC10: =IFERROR(__xludf.DUMMYFUNCTION("""COMPUTED_VALUE"""),20.0) -> 20 | AD10: =IFERROR(__xludf.DUMMYFUNCTION("""COMPUTED_VALUE"""),45.0) -> 45
A11: =IFERROR(__xludf.DUMMYFUNCTION("""COMPUTED_VALUE"""),"Amateur") -> Amateur | B11: =IFERROR(__xludf.DUMMYFUNCTION("""COMPUTED_VALUE"""),"RSC007571") -> RSC007571 | C11: =IFERROR(__xludf.DUMMYFUNCTION("""COMPUTED_VALUE"""),"StephM2_") -> StephM2_ | D11: =IFERROR(__xludf.DUMMYFUNCTION("""COMPUTED_VALUE"""),"Garlic Knots") -> Garlic Knots | E11: =IFERROR(__xludf.DUMMYFUNCTION("""COMPUTED_VALUE"""),"N/A") -> N/A | F11: =IFERROR(__xludf.DUMMYFUNCTION("""COMPUTED_VALUE"""),76.58843761915671) -> 76.588438 | G11: =IFERROR(__xludf.DUMMYFUNCTION("""COMPUTED_VALUE"""),67.59713632398024) -> 67.597136 | H11: =IFERROR(__xludf.DUMMYFUNCTION("""COMPUTED_VALUE"""),72.09278697156847) -> 72.092787 | I11: =IFERROR(__xludf.DUMMYFUNCTION("""COMPUTED_VALUE"""),47.0) -> 47 | J11: =IFERROR(__xludf.DUMMYFUNCTION("IFERROR(FILTER(Stats!$F:$Z,(Stats!$A:$A=$A11)*(Stats!$B:$B=$B11)))"),21.0) -> 21 | K11: =IFERROR(__xludf.DUMMYFUNCTION("""COMPUTED_VALUE"""),26.0) -> 26 | L11: =IFERROR(__xludf.DUMMYFUNCTION("""COMPUTED_VALUE"""),0.44680851063829785) -> 0.44680851 | M11: =IFERROR(__xludf.DUMMYFUNCTION("""COMPUTED_VALUE"""),13.0) -> 13 | N11: =IFERROR(__xludf.DUMMYFUNCTION("""COMPUTED_VALUE"""),17651.0) -> 17651 | O11: =IFERROR(__xludf.DUMMYFUNCTION("""COMPUTED_VALUE"""),42.0) -> 42 | P11: =IFERROR(__xludf.DUMMYFUNCTION("""COMPUTED_VALUE"""),22.0) -> 22 | Q11: =IFERROR(__xludf.DUMMYFUNCTION("""COMPUTED_VALUE"""),65.0) -> 65 | R11: =IFERROR(__xludf.DUMMYFUNCTION("""COMPUTED_VALUE"""),133.0) -> 133 | S11: =IFERROR(__xludf.DUMMYFUNCTION("""COMPUTED_VALUE"""),0.3157894736842105) -> 0.31578947 | T11: =IFERROR(__xludf.DUMMYFUNCTION("""COMPUTED_VALUE"""),375.5531914893617) -> 375.55319 | U11: =IFERROR(__xludf.DUMMYFUNCTION("""COMPUTED_VALUE"""),0.8936170212765957) -> 0.89361702 | V11: =IFERROR(__xludf.DUMMYFUNCTION("""COMPUTED_VALUE"""),0.46808510638297873) -> 0.46808511 | W11: =IFERROR(__xludf.DUMMYFUNCTION("""COMPUTED_VALUE"""),1.3829787234042554) -> 1.3829787 | X11: =IFERROR(__xludf.DUMMYFUNCTION("""COMPUTED_VALUE"""),2.8297872340425534) -> 2.8297872 | Y11: =IFERROR(__xludf.DUMMYFUNCTION("""COMPUTED_VALUE"""),10.0) -> 10 | Z11: =IFERROR(__xludf.DUMMYFUNCTION("""COMPUTED_VALUE"""),4.0) -> 4 | AA11: =IFERROR(__xludf.DUMMYFUNCTION("""COMPUTED_VALUE"""),0.0) -> 0 | AB11: =IFERROR(__xludf.DUMMYFUNCTION("""COMPUTED_VALUE"""),9.0) -> 9 | AC11: =IFERROR(__xludf.DUMMYFUNCTION("""COMPUTED_VALUE"""),61.0) -> 61 | AD11: =IFERROR(__xludf.DUMMYFUNCTION("""COMPUTED_VALUE"""),24.0) -> 24
A12: =IFERROR(__xludf.DUMMYFUNCTION("""COMPUTED_VALUE"""),"Amateur") -> Amateur | B12: =IFERROR(__xludf.DUMMYFUNCTION("""COMPUTED_VALUE"""),"RSC000086") -> RSC000086 | C12: =IFERROR(__xludf.DUMMYFUNCTION("""COMPUTED_VALUE"""),"Stale Popcorn") -> Stale Popcorn | D12: =IFERROR(__xludf.DUMMYFUNCTION("""COMPUTED_VALUE"""),"Winter Fresh HR Violation") -> Winter Fresh HR Violation | E12: =IFERROR(__xludf.DUMMYFUNCTION("""COMPUTED_VALUE"""),"N/A N/A") -> N/A N/A | F12: =IFERROR(__xludf.DUMMYFUNCTION("""COMPUTED_VALUE"""),70.94856001035916) -> 70.94856 | G12: =IFERROR(__xludf.DUMMYFUNCTION("""COMPUTED_VALUE"""),66.9422663409696) -> 66.942266 | H12: =IFERROR(__xludf.DUMMYFUNCTION("""COMPUTED_VALUE"""),68.94541317566438) -> 68.945413 | I12: =IFERROR(__xludf.DUMMYFUNCTION("""COMPUTED_VALUE"""),32.0) -> 32 | J12: =IFERROR(__xludf.DUMMYFUNCTION("IFERROR(FILTER(Stats!$F:$Z,(Stats!$A:$A=$A12)*(Stats!$B:$B=$B12)))"),15.0) -> 15 | K12: =IFERROR(__xludf.DUMMYFUNCTION("""COMPUTED_VALUE"""),17.0) -> 17 | L12: =IFERROR(__xludf.DUMMYFUNCTION("""COMPUTED_VALUE"""),0.46875) -> 0.46875 | M12: =IFERROR(__xludf.DUMMYFUNCTION("""COMPUTED_VALUE"""),7.0) -> 7 | N12: =IFERROR(__xludf.DUMMYFUNCTION("""COMPUTED_VALUE"""),10264.0) -> 10264 | O12: =IFERROR(__xludf.DUMMYFUNCTION("""COMPUTED_VALUE"""),30.0) -> 30 | P12: =IFERROR(__xludf.DUMMYFUNCTION("""COMPUTED_VALUE"""),15.0) -> 15 | Q12: =IFERROR(__xludf.DUMMYFUNCTION("""COMPUTED_VALUE"""),21.0) -> 21 | R12: =IFERROR(__xludf.DUMMYFUNCTION("""COMPUTED_VALUE"""),103.0) -> 103 | S12: =IFERROR(__xludf.DUMMYFUNCTION("""COMPUTED_VALUE"""),0.2912621359223301) -> 0.29126214 | T12: =IFERROR(__xludf.DUMMYFUNCTION("""COMPUTED_VALUE"""),320.75) -> 320.75 | U12: =IFERROR(__xludf.DUMMYFUNCTION("""COMPUTED_VALUE"""),0.9375) -> 0.9375 | V12: =IFERROR(__xludf.DUMMYFUNCTION("""COMPUTED_VALUE"""),0.46875) -> 0.46875 | W12: =IFERROR(__xludf.DUMMYFUNCTION("""COMPUTED_VALUE"""),0.65625) -> 0.65625 | X12: =IFERROR(__xludf.DUMMYFUNCTION("""COMPUTED_VALUE"""),3.21875) -> 3.21875 | Y12: =IFERROR(__xludf.DUMMYFUNCTION("""COMPUTED_VALUE"""),3.0) -> 3 | Z12: =IFERROR(__xludf.DUMMYFUNCTION("""COMPUTED_VALUE"""),3.0) -> 3 | AA12: =IFERROR(__xludf.DUMMYFUNCTION("""COMPUTED_VALUE"""),0.0) -> 0 | AB12: =IFERROR(__xludf.DUMMYFUNCTION("""COMPUTED_VALUE"""),1.0) -> 1 | AC12: =IFERROR(__xludf.DUMMYFUNCTION("""COMPUTED_VALUE"""),50.0) -> 50 | AD12: =IFERROR(__xludf.DUMMYFUNCTION("""COMPUTED_VALUE"""),20.0) -> 20
A13: =IFERROR(__xludf.DUMMYFUNCTION("""COMPUTED_VALUE"""),"Amateur") -> Amateur | B13: =IFERROR(__xludf.DUMMYFUNCTION("""COMPUTED_VALUE"""),"RSC008441") -> RSC008441 | C13: =IFERROR(__xludf.DUMMYFUNCTION("""COMPUTED_VALUE"""),"Izumi._._.") -> Izumi._._. | D13: =IFERROR(__xludf.DUMMYFUNCTION("""COMPUTED_VALUE"""),"HR Violation") -> HR Violation | E13: =IFERROR(__xludf.DUMMYFUNCTION("""COMPUTED_VALUE"""),"N/A") -> N/A | F13: =IFERROR(__xludf.DUMMYFUNCTION("""COMPUTED_VALUE"""),73.11410936672084) -> 73.114109 | G13: =IFERROR(__xludf.DUMMYFUNCTION("""COMPUTED_VALUE"""),64.08128424845688) -> 64.081284 | H13: =IFERROR(__xludf.DUMMYFUNCTION("""COMPUTED_VALUE"""),68.59769680758886) -> 68.597697 | I13: =IFERROR(__xludf.DUMMYFUNCTION("""COMPUTED_VALUE"""),56.0) -> 56 | J13: =IFERROR(__xludf.DUMMYFUNCTION("IFERROR(FILTER(Stats!$F:$Z,(Stats!$A:$A=$A13)*(Stats!$B:$B=$B13)))"),27.0) -> 27 | K13: =IFERROR(__xludf.DUMMYFUNCTION("""COMPUTED_VALUE"""),29.0) -> 29 | L13: =IFERROR(__xludf.DUMMYFUNCTION("""COMPUTED_VALUE"""),0.48214285714285715) -> 0.48214286 | M13: =IFERROR(__xludf.DUMMYFUNCTION("""COMPUTED_VALUE"""),13.0) -> 13 | N13: =IFERROR(__xludf.DUMMYFUNCTION("""COMPUTED_VALUE"""),19855.0) -> 19855 | O13: =IFERROR(__xludf.DUMMYFUNCTION("""COMPUTED_VALUE"""),52.0) -> 52 | P13: =IFERROR(__xludf.DUMMYFUNCTION("""COMPUTED_VALUE"""),25.0) -> 25 | Q13: =IFERROR(__xludf.DUMMYFUNCTION("""COMPUTED_VALUE"""),71.0) -> 71 | R13: =IFERROR(__xludf.DUMMYFUNCTION("""COMPUTED_VALUE"""),146.0) -> 146 | S13: =IFERROR(__xludf.DUMMYFUNCTION("""COMPUTED_VALUE"""),0.3561643835616438) -> 0.35616438 | T13: =IFERROR(__xludf.DUMMYFUNCTION("""COMPUTED_VALUE"""),354.55357142857144) -> 354.55357 | U13: =IFERROR(__xludf.DUMMYFUNCTION("""COMPUTED_VALUE"""),0.9285714285714286) -> 0.92857143 | V13: =IFERROR(__xludf.DUMMYFUNCTION("""COMPUTED_VALUE"""),0.44642857142857145) -> 0.44642857 | W13: =IFERROR(__xludf.DUMMYFUNCTION("""COMPUTED_VALUE"""),1.2678571428571428) -> 1.2678571 | X13: =IFERROR(__xludf.DUMMYFUNCTION("""COMPUTED_VALUE"""),2.607142857142857) -> 2.6071429 | Y13: =IFERROR(__xludf.DUMMYFUNCTION("""COMPUTED_VALUE"""),7.0) -> 7 | Z13: =IFERROR(__xludf.DUMMYFUNCTION("""COMPUTED_VALUE"""),0.0) -> 0 | AA13: =IFERROR(__xludf.DUMMYFUNCTION("""COMPUTED_VALUE"""),0.0) -> 0 | AB13: =IFERROR(__xludf.DUMMYFUNCTION("""COMPUTED_VALUE"""),9.0) -> 9 | AC13: =IFERROR(__xludf.DUMMYFUNCTION("""COMPUTED_VALUE"""),17.0) -> 17 | AD13: =IFERROR(__xludf.DUMMYFUNCTION("""COMPUTED_VALUE"""),42.0) -> 42
A14: =IFERROR(__xludf.DUMMYFUNCTION("""COMPUTED_VALUE"""),"Amateur") -> Amateur | B14: =IFERROR(__xludf.DUMMYFUNCTION("""COMPUTED_VALUE"""),"RSC000963") -> RSC000963 | C14: =IFERROR(__xludf.DUMMYFUNCTION("""COMPUTED_VALUE"""),"Sup3rm4n") -> Sup3rm4n | D14: =IFERROR(__xludf.DUMMYFUNCTION("""COMPUTED_VALUE"""),"Bombers") -> Bombers | E14: =IFERROR(__xludf.DUMMYFUNCTION("""COMPUTED_VALUE"""),"N/A") -> N/A | F14: =IFERROR(__xludf.DUMMYFUNCTION("""COMPUTED_VALUE"""),69.69412017105158) -> 69.69412 | G14: =IFERROR(__xludf.DUMMYFUNCTION("""COMPUTED_VALUE"""),67.41423923974222) -> 67.414239 | H14: =IFERROR(__xludf.DUMMYFUNCTION("""COMPUTED_VALUE"""),68.5541797053969) -> 68.55418 | I14: =IFERROR(__xludf.DUMMYFUNCTION("""COMPUTED_VALUE"""),55.0) -> 55 | J14: =IFERROR(__xludf.DUMMYFUNCTION("IFERROR(FILTER(Stats!$F:$Z,(Stats!$A:$A=$A14)*(Stats!$B:$B=$B14)))"),38.0) -> 38 | K14: =IFERROR(__xludf.DUMMYFUNCTION("""COMPUTED_VALUE"""),17.0) -> 17 | L14: =IFERROR(__xludf.DUMMYFUNCTION("""COMPUTED_VALUE"""),0.6909090909090909) -> 0.69090909 | M14: =IFERROR(__xludf.DUMMYFUNCTION("""COMPUTED_VALUE"""),16.0) -> 16 | N14: =IFERROR(__xludf.DUMMYFUNCTION("""COMPUTED_VALUE"""),18891.0) -> 18891 | O14: =IFERROR(__xludf.DUMMYFUNCTION("""COMPUTED_VALUE"""),54.0) -> 54 | P14: =IFERROR(__xludf.DUMMYFUNCTION("""COMPUTED_VALUE"""),24.0) -> 24 | Q14: =IFERROR(__xludf.DUMMYFUNCTION("""COMPUTED_VALUE"""),49.0) -> 49 | R14: =IFERROR(__xludf.DUMMYFUNCTION("""COMPUTED_VALUE"""),159.0) -> 159 | S14: =IFERROR(__xludf.DUMMYFUNCTION("""COMPUTED_VALUE"""),0.33962264150943394) -> 0.33962264 | T14: =IFERROR(__xludf.DUMMYFUNCTION("""COMPUTED_VALUE"""),343.4727272727273) -> 343.47273 | U14: =IFERROR(__xludf.DUMMYFUNCTION("""COMPUTED_VALUE"""),0.9818181818181818) -> 0.98181818 | V14: =IFERROR(__xludf.DUMMYFUNCTION("""COMPUTED_VALUE"""),0.43636363636363634) -> 0.43636364 | W14: =IFERROR(__xludf.DUMMYFUNCTION("""COMPUTED_VALUE"""),0.8909090909090909) -> 0.89090909 | X14: =IFERROR(__xludf.DUMMYFUNCTION("""COMPUTED_VALUE"""),2.890909090909091) -> 2.8909091 | Y14: =IFERROR(__xludf.DUMMYFUNCTION("""COMPUTED_VALUE"""),10.0) -> 10 | Z14: =IFERROR(__xludf.DUMMYFUNCTION("""COMPUTED_VALUE"""),5.0) -> 5 | AA14: =IFERROR(__xludf.DUMMYFUNCTION("""COMPUTED_VALUE"""),0.0) -> 0 | AB14: =IFERROR(__xludf.DUMMYFUNCTION("""COMPUTED_VALUE"""),4.0) -> 4 | AC14: =IFERROR(__xludf.DUMMYFUNCTION("""COMPUTED_VALUE"""),45.0) -> 45 | AD14: =IFERROR(__xludf.DUMMYFUNCTION("""COMPUTED_VALUE"""),43.0) -> 43
A15: =IFERROR(__xludf.DUMMYFUNCTION("""COMPUTED_VALUE"""),"Amateur") -> Amateur | B15: =IFERROR(__xludf.DUMMYFUNCTION("""COMPUTED_VALUE"""),"RSC008227") -> RSC008227 | C15: =IFERROR(__xludf.DUMMYFUNCTION("""COMPUTED_VALUE"""),"batman") -> batman | D15: =IFERROR(__xludf.DUMMYFUNCTION("""COMPUTED_VALUE"""),"Electric Eels") -> Electric Eels | E15: =IFERROR(__xludf.DUMMYFUNCTION("""COMPUTED_VALUE"""),"N/A") -> N/A | F15: =IFERROR(__xludf.DUMMYFUNCTION("""COMPUTED_VALUE"""),71.51301738215024) -> 71.513017 | G15: =IFERROR(__xludf.DUMMYFUNCTION("""COMPUTED_VALUE"""),62.75653641242059) -> 62.756536 | H15: =IFERROR(__xludf.DUMMYFUNCTION("""COMPUTED_VALUE"""),67.1347768972854) -> 67.134777 | I15: =IFERROR(__xludf.DUMMYFUNCTION("""COMPUTED_VALUE"""),12.0) -> 12 | J15: =IFERROR(__xludf.DUMMYFUNCTION("IFERROR(FILTER(Stats!$F:$Z,(Stats!$A:$A=$A15)*(Stats!$B:$B=$B15)))"),8.0) -> 8 | K15: =IFERROR(__xludf.DUMMYFUNCTION("""COMPUTED_VALUE"""),4.0) -> 4 | L15: =IFERROR(__xludf.DUMMYFUNCTION("""COMPUTED_VALUE"""),0.6666666666666666) -> 0.66666667 | M15: =IFERROR(__xludf.DUMMYFUNCTION("""COMPUTED_VALUE"""),1.0) -> 1 | N15: =IFERROR(__xludf.DUMMYFUNCTION("""COMPUTED_VALUE"""),4076.0) -> 4076 | O15: =IFERROR(__xludf.DUMMYFUNCTION("""COMPUTED_VALUE"""),8.0) -> 8 | P15: =IFERROR(__xludf.DUMMYFUNCTION("""COMPUTED_VALUE"""),9.0) -> 9 | Q15: =IFERROR(__xludf.DUMMYFUNCTION("""COMPUTED_VALUE"""),15.0) -> 15 | R15: =IFERROR(__xludf.DUMMYFUNCTION("""COMPUTED_VALUE"""),26.0) -> 26 | S15: =IFERROR(__xludf.DUMMYFUNCTION("""COMPUTED_VALUE"""),0.3076923076923077) -> 0.30769231 | T15: =IFERROR(__xludf.DUMMYFUNCTION("""COMPUTED_VALUE"""),339.6666666666667) -> 339.66667 | U15: =IFERROR(__xludf.DUMMYFUNCTION("""COMPUTED_VALUE"""),0.6666666666666666) -> 0.66666667 | V15: =IFERROR(__xludf.DUMMYFUNCTION("""COMPUTED_VALUE"""),0.75) -> 0.75 | W15: =IFERROR(__xludf.DUMMYFUNCTION("""COMPUTED_VALUE"""),1.25) -> 1.25 | X15: =IFERROR(__xludf.DUMMYFUNCTION("""COMPUTED_VALUE"""),2.1666666666666665) -> 2.1666667 | Y15: =IFERROR(__xludf.DUMMYFUNCTION("""COMPUTED_VALUE"""),2.0) -> 2 | Z15: =IFERROR(__xludf.DUMMYFUNCTION("""COMPUTED_VALUE"""),1.0) -> 1 | AA15: =IFERROR(__xludf.DUMMYFUNCTION("""COMPUTED_VALUE"""),0.0) -> 0 | AB15: =IFERROR(__xludf.DUMMYFUNCTION("""COMPUTED_VALUE"""),2.0) -> 2 | AC15: =IFERROR(__xludf.DUMMYFUNCTION("""COMPUTED_VALUE"""),9.0) -> 9 | AD15: =IFERROR(__xludf.DUMMYFUNCTION("""COMPUTED_VALUE"""),14.0) -> 14
A16: =IFERROR(__xludf.DUMMYFUNCTION("""COMPUTED_VALUE"""),"Amateur") -> Amateur | B16: =IFERROR(__xludf.DUMMYFUNCTION("""COMPUTED_VALUE"""),"RSC008136") -> RSC008136 | C16: =IFERROR(__xludf.DUMMYFUNCTION("""COMPUTED_VALUE"""),"GeneralLeigh91") -> GeneralLeigh91 | D16: =IFERROR(__xludf.DUMMYFUNCTION("""COMPUTED_VALUE"""),"Winter Fresh Chimera") -> Winter Fresh Chimera | E16: =IFERROR(__xludf.DUMMYFUNCTION("""COMPUTED_VALUE"""),"N/A N/A") -> N/A N/A | F16: =IFERROR(__xludf.DUMMYFUNCTION("""COMPUTED_VALUE"""),62.23499587117157) -> 62.234996 | G16: =IFERROR(__xludf.DUMMYFUNCTION("""COMPUTED_VALUE"""),66.60528714472376) -> 66.605287 | H16: =IFERROR(__xludf.DUMMYFUNCTION("""COMPUTED_VALUE"""),64.42014150794766) -> 64.420142 | I16: =IFERROR(__xludf.DUMMYFUNCTION("""COMPUTED_VALUE"""),50.0) -> 50 | J16: =IFERROR(__xludf.DUMMYFUNCTION("IFERROR(FILTER(Stats!$F:$Z,(Stats!$A:$A=$A16)*(Stats!$B:$B=$B16)))"),31.0) -> 31 | K16: =IFERROR(__xludf.DUMMYFUNCTION("""COMPUTED_VALUE"""),19.0) -> 19 | L16: =IFERROR(__xludf.DUMMYFUNCTION("""COMPUTED_VALUE"""),0.62) -> 0.62 | M16: =IFERROR(__xludf.DUMMYFUNCTION("""COMPUTED_VALUE"""),11.0) -> 11 | N16: =IFERROR(__xludf.DUMMYFUNCTION("""COMPUTED_VALUE"""),17383.0) -> 17383 | O16: =IFERROR(__xludf.DUMMYFUNCTION("""COMPUTED_VALUE"""),48.0) -> 48 | P16: =IFERROR(__xludf.DUMMYFUNCTION("""COMPUTED_VALUE"""),29.0) -> 29 | Q16: =IFERROR(__xludf.DUMMYFUNCTION("""COMPUTED_VALUE"""),63.0) -> 63 | R16: =IFERROR(__xludf.DUMMYFUNCTION("""COMPUTED_VALUE"""),121.0) -> 121 | S16: =IFERROR(__xludf.DUMMYFUNCTION("""COMPUTED_VALUE"""),0.39669421487603307) -> 0.39669421 | T16: =IFERROR(__xludf.DUMMYFUNCTION("""COMPUTED_VALUE"""),347.66) -> 347.66 | U16: =IFERROR(__xludf.DUMMYFUNCTION("""COMPUTED_VALUE"""),0.96) -> 0.96 | V16: =IFERROR(__xludf.DUMMYFUNCTION("""COMPUTED_VALUE"""),0.58) -> 0.58 | W16: =IFERROR(__xludf.DUMMYFUNCTION("""COMPUTED_VALUE"""),1.26) -> 1.26 | X16: =IFERROR(__xludf.DUMMYFUNCTION("""COMPUTED_VALUE"""),2.42) -> 2.42 | Y16: =IFERROR(__xludf.DUMMYFUNCTION("""COMPUTED_VALUE"""),7.0) -> 7 | Z16: =IFERROR(__xludf.DUMMYFUNCTION("""COMPUTED_VALUE"""),4.0) -> 4 | AA16: =IFERROR(__xludf.DUMMYFUNCTION("""COMPUTED_VALUE"""),2.0) -> 2 | AB16: =IFERROR(__xludf.DUMMYFUNCTION("""COMPUTED_VALUE"""),7.0) -> 7 | AC16: =IFERROR(__xludf.DUMMYFUNCTION("""COMPUTED_VALUE"""),32.0) -> 32 | AD16: =IFERROR(__xludf.DUMMYFUNCTION("""COMPUTED_VALUE"""),33.0) -> 33
A17: =IFERROR(__xludf.DUMMYFUNCTION("""COMPUTED_VALUE"""),"Amateur") -> Amateur | B17: =IFERROR(__xludf.DUMMYFUNCTION("""COMPUTED_VALUE"""),"RSC008092") -> RSC008092 | C17: =IFERROR(__xludf.DUMMYFUNCTION("""COMPUTED_VALUE"""),"ImPodz") -> ImPodz | D17: =IFERROR(__xludf.DUMMYFUNCTION("""COMPUTED_VALUE"""),"Electric Eels") -> Electric Eels | E17: =IFERROR(__xludf.DUMMYFUNCTION("""COMPUTED_VALUE"""),"N/A") -> N/A | F17: =IFERROR(__xludf.DUMMYFUNCTION("""COMPUTED_VALUE"""),64.13553882675204) -> 64.135539 | G17: =IFERROR(__xludf.DUMMYFUNCTION("""COMPUTED_VALUE"""),59.7024205811802) -> 59.702421 | H17: =IFERROR(__xludf.DUMMYFUNCTION("""COMPUTED_VALUE"""),61.918979703966116) -> 61.91898 | I17: =IFERROR(__xludf.DUMMYFUNCTION("""COMPUTED_VALUE"""),28.0) -> 28 | J17: =IFERROR(__xludf.DUMMYFUNCTION("IFERROR(FILTER(Stats!$F:$Z,(Stats!$A:$A=$A17)*(Stats!$B:$B=$B17)))"),13.0) -> 13 | K17: =IFERROR(__xludf.DUMMYFUNCTION("""COMPUTED_VALUE"""),15.0) -> 15 | L17: =IFERROR(__xludf.DUMMYFUNCTION("""COMPUTED_VALUE"""),0.4642857142857143) -> 0.46428571 | M17: =IFERROR(__xludf.DUMMYFUNCTION("""COMPUTED_VALUE"""),6.0) -> 6 | N17: =IFERROR(__xludf.DUMMYFUNCTION("""COMPUTED_VALUE"""),10042.0) -> 10042 | O17: =IFERROR(__xludf.DUMMYFUNCTION("""COMPUTED_VALUE"""),24.0) -> 24 | P17: =IFERROR(__xludf.DUMMYFUNCTION("""COMPUTED_VALUE"""),11.0) -> 11 | Q17: =IFERROR(__xludf.DUMMYFUNCTION("""COMPUTED_VALUE"""),36.0) -> 36 | R17: =IFERROR(__xludf.DUMMYFUNCTION("""COMPUTED_VALUE"""),66.0) -> 66 | S17: =IFERROR(__xludf.DUMMYFUNCTION("""COMPUTED_VALUE"""),0.36363636363636365) -> 0.36363636 | T17: =IFERROR(__xludf.DUMMYFUNCTION("""COMPUTED_VALUE"""),358.64285714285717) -> 358.64286 | U17: =IFERROR(__xludf.DUMMYFUNCTION("""COMPUTED_VALUE"""),0.8571428571428571) -> 0.85714286 | V17: =IFERROR(__xludf.DUMMYFUNCTION("""COMPUTED_VALUE"""),0.39285714285714285) -> 0.39285714 | W17: =IFERROR(__xludf.DUMMYFUNCTION("""COMPUTED_VALUE"""),1.2857142857142858) -> 1.2857143 | X17: =IFERROR(__xludf.DUMMYFUNCTION("""COMPUTED_VALUE"""),2.357142857142857) -> 2.3571429 | Y17: =IFERROR(__xludf.DUMMYFUNCTION("""COMPUTED_VALUE"""),2.0) -> 2 | Z17: =IFERROR(__xludf.DUMMYFUNCTION("""COMPUTED_VALUE"""),3.0) -> 3 | AA17: =IFERROR(__xludf.DUMMYFUNCTION("""COMPUTED_VALUE"""),0.0) -> 0 | AB17: =IFERROR(__xludf.DUMMYFUNCTION("""COMPUTED_VALUE"""),4.0) -> 4 | AC17: =IFERROR(__xludf.DUMMYFUNCTION("""COMPUTED_VALUE"""),21.0) -> 21 | AD17: =IFERROR(__xludf.DUMMYFUNCTION("""COMPUTED_VALUE"""),14.0) -> 14
A18: =IFERROR(__xludf.DUMMYFUNCTION("""COMPUTED_VALUE"""),"Amateur") -> Amateur | B18: =IFERROR(__xludf.DUMMYFUNCTION("""COMPUTED_VALUE"""),"RSC007270") -> RSC007270 | C18: =IFERROR(__xludf.DUMMYFUNCTION("""COMPUTED_VALUE"""),"D0pey killer") -> D0pey killer | D18: =IFERROR(__xludf.DUMMYFUNCTION("""COMPUTED_VALUE"""),"Electric Eels") -> Electric Eels | E18: =IFERROR(__xludf.DUMMYFUNCTION("""COMPUTED_VALUE"""),"N/A") -> N/A | F18: =IFERROR(__xludf.DUMMYFUNCTION("""COMPUTED_VALUE"""),64.03248701807968) -> 64.032487 | G18: =IFERROR(__xludf.DUMMYFUNCTION("""COMPUTED_VALUE"""),59.51264956267918) -> 59.51265 | H18: =IFERROR(__xludf.DUMMYFUNCTION("""COMPUTED_VALUE"""),61.772568290379425) -> 61.772568 | I18: =IFERROR(__xludf.DUMMYFUNCTION("""COMPUTED_VALUE"""),48.0) -> 48 | J18: =IFERROR(__xludf.DUMMYFUNCTION("IFERROR(FILTER(Stats!$F:$Z,(Stats!$A:$A=$A18)*(Stats!$B:$B=$B18)))"),24.0) -> 24 | K18: =IFERROR(__xludf.DUMMYFUNCTION("""COMPUTED_VALUE"""),24.0) -> 24 | L18: =IFERROR(__xludf.DUMMYFUNCTION("""COMPUTED_VALUE"""),0.5) -> 0.5 | M18: =IFERROR(__xludf.DUMMYFUNCTION("""COMPUTED_VALUE"""),4.0) -> 4 | N18: =IFERROR(__xludf.DUMMYFUNCTION("""COMPUTED_VALUE"""),15443.0) -> 15443 | O18: =IFERROR(__xludf.DUMMYFUNCTION("""COMPUTED_VALUE"""),35.0) -> 35 | P18: =IFERROR(__xludf.DUMMYFUNCTION("""COMPUTED_VALUE"""),24.0) -> 24 | Q18: =IFERROR(__xludf.DUMMYFUNCTION("""COMPUTED_VALUE"""),49.0) -> 49 | R18: =IFERROR(__xludf.DUMMYFUNCTION("""COMPUTED_VALUE"""),118.0) -> 118 | S18: =IFERROR(__xludf.DUMMYFUNCTION("""COMPUTED_VALUE"""),0.2966101694915254) -> 0.29661017 | T18: =IFERROR(__xludf.DUMMYFUNCTION("""COMPUTED_VALUE"""),321.7291666666667) -> 321.72917 | U18: =IFERROR(__xludf.DUMMYFUNCTION("""COMPUTED_VALUE"""),0.7291666666666666) -> 0.72916667 | V18: =IFERROR(__xludf.DUMMYFUNCTION("""COMPUTED_VALUE"""),0.5) -> 0.5 | W18: =IFERROR(__xludf.DUMMYFUNCTION("""COMPUTED_VALUE"""),1.0208333333333333) -> 1.0208333 | X18: =IFERROR(__xludf.DUMMYFUNCTION("""COMPUTED_VALUE"""),2.4583333333333335) -> 2.4583333 | Y18: =IFERROR(__xludf.DUMMYFUNCTION("""COMPUTED_VALUE"""),7.0) -> 7 | Z18: =IFERROR(__xludf.DUMMYFUNCTION("""COMPUTED_VALUE"""),2.0) -> 2 | AA18: =IFERROR(__xludf.DUMMYFUNCTION("""COMPUTED_VALUE"""),2.0) -> 2 | AB18: =IFERROR(__xludf.DUMMYFUNCTION("""COMPUTED_VALUE"""),7.0) -> 7 | AC18: =IFERROR(__xludf.DUMMYFUNCTION("""COMPUTED_VALUE"""),43.0) -> 43 | AD18: =IFERROR(__xludf.DUMMYFUNCTION("""COMPUTED_VALUE"""),33.0) -> 33
A19: =IFERROR(__xludf.DUMMYFUNCTION("""COMPUTED_VALUE"""),"Amateur") -> Amateur | B19: =IFERROR(__xludf.DUMMYFUNCTION("""COMPUTED_VALUE"""),"RSC008193") -> RSC008193 | C19: =IFERROR(__xludf.DUMMYFUNCTION("""COMPUTED_VALUE"""),"RL Camaro") -> RL Camaro | D19: =IFERROR(__xludf.DUMMYFUNCTION("""COMPUTED_VALUE"""),"Chimera") -> Chimera | E19: =IFERROR(__xludf.DUMMYFUNCTION("""COMPUTED_VALUE"""),"N/A") -> N/A | F19: =IFERROR(__xludf.DUMMYFUNCTION("""COMPUTED_VALUE"""),58.53108837612528) -> 58.531088 | G19: =IFERROR(__xludf.DUMMYFUNCTION("""COMPUTED_VALUE"""),59.46436549120326) -> 59.464365 | H19: =IFERROR(__xludf.DUMMYFUNCTION("""COMPUTED_VALUE"""),58.99772693366427) -> 58.997727 | I19: =IFERROR(__xludf.DUMMYFUNCTION("""COMPUTED_VALUE"""),51.0) -> 51 | J19: =IFERROR(__xludf.DUMMYFUNCTION("IFERROR(FILTER(Stats!$F:$Z,(Stats!$A:$A=$A19)*(Stats!$B:$B=$B19)))"),27.0) -> 27 | K19: =IFERROR(__xludf.DUMMYFUNCTION("""COMPUTED_VALUE"""),24.0) -> 24 | L19: =IFERROR(__xludf.DUMMYFUNCTION("""COMPUTED_VALUE"""),0.5294117647058824) -> 0.52941176 | M19: =IFERROR(__xludf.DUMMYFUNCTION("""COMPUTED_VALUE"""),10.0) -> 10 | N19: =IFERROR(__xludf.DUMMYFUNCTION("""COMPUTED_VALUE"""),16903.0) -> 16903 | O19: =IFERROR(__xludf.DUMMYFUNCTION("""COMPUTED_VALUE"""),46.0) -> 46 | P19: =IFERROR(__xludf.DUMMYFUNCTION("""COMPUTED_VALUE"""),24.0) -> 24 | Q19: =IFERROR(__xludf.DUMMYFUNCTION("""COMPUTED_VALUE"""),40.0) -> 40 | R19: =IFERROR(__xludf.DUMMYFUNCTION("""COMPUTED_VALUE"""),117.0) -> 117 | S19: =IFERROR(__xludf.DUMMYFUNCTION("""COMPUTED_VALUE"""),0.39316239316239315) -> 0.39316239 | T19: =IFERROR(__xludf.DUMMYFUNCTION("""COMPUTED_VALUE"""),331.4313725490196) -> 331.43137 | U19: =IFERROR(__xludf.DUMMYFUNCTION("""COMPUTED_VALUE"""),0.9019607843137255) -> 0.90196078 | V19: =IFERROR(__xludf.DUMMYFUNCTION("""COMPUTED_VALUE"""),0.47058823529411764) -> 0.47058824 | W19: =IFERROR(__xludf.DUMMYFUNCTION("""COMPUTED_VALUE"""),0.7843137254901961) -> 0.78431373 | X19: =IFERROR(__xludf.DUMMYFUNCTION("""COMPUTED_VALUE"""),2.2941176470588234) -> 2.2941176 | Y19: =IFERROR(__xludf.DUMMYFUNCTION("""COMPUTED_VALUE"""),4.0) -> 4 | Z19: =IFERROR(__xludf.DUMMYFUNCTION("""COMPUTED_VALUE"""),3.0) -> 3 | AA19: =IFERROR(__xludf.DUMMYFUNCTION("""COMPUTED_VALUE"""),0.0) -> 0 | AB19: =IFERROR(__xludf.DUMMYFUNCTION("""COMPUTED_VALUE"""),3.0) -> 3 | AC19: =IFERROR(__xludf.DUMMYFUNCTION("""COMPUTED_VALUE"""),23.0) -> 23 | AD19: =IFERROR(__xludf.DUMMYFUNCTION("""COMPUTED_VALUE"""),34.0) -> 34
A20: =IFERROR(__xludf.DUMMYFUNCTION("""COMPUTED_VALUE"""),"Amateur") -> Amateur | B20: =IFERROR(__xludf.DUMMYFUNCTION("""COMPUTED_VALUE"""),"RSC007852") -> RSC007852 | C20: =IFERROR(__xludf.DUMMYFUNCTION("""COMPUTED_VALUE"""),"Medicmac121") -> Medicmac121 | D20: =IFERROR(__xludf.DUMMYFUNCTION("""COMPUTED_VALUE"""),"Garlic Knots") -> Garlic Knots | E20: =IFERROR(__xludf.DUMMYFUNCTION("""COMPUTED_VALUE"""),"N/A") -> N/A | F20: =IFERROR(__xludf.DUMMYFUNCTION("""COMPUTED_VALUE"""),55.6750799410066) -> 55.67508 | G20: =IFERROR(__xludf.DUMMYFUNCTION("""COMPUTED_VALUE"""),59.29091412043735) -> 59.290914 | H20: =IFERROR(__xludf.DUMMYFUNCTION("""COMPUTED_VALUE"""),57.482997030721975) -> 57.482997 | I20: =IFERROR(__xludf.DUMMYFUNCTION("""COMPUTED_VALUE"""),44.0) -> 44 | J20: =IFERROR(__xludf.DUMMYFUNCTION("IFERROR(FILTER(Stats!$F:$Z,(Stats!$A:$A=$A20)*(Stats!$B:$B=$B20)))"),20.0) -> 20 | K20: =IFERROR(__xludf.DUMMYFUNCTION("""COMPUTED_VALUE"""),24.0) -> 24 | L20: =IFERROR(__xludf.DUMMYFUNCTION("""COMPUTED_VALUE"""),0.45454545454545453) -> 0.45454545 | M20: =IFERROR(__xludf.DUMMYFUNCTION("""COMPUTED_VALUE"""),5.0) -> 5 | N20: =IFERROR(__xludf.DUMMYFUNCTION("""COMPUTED_VALUE"""),13777.0) -> 13777 | O20: =IFERROR(__xludf.DUMMYFUNCTION("""COMPUTED_VALUE"""),37.0) -> 37 | P20: =IFERROR(__xludf.DUMMYFUNCTION("""COMPUTED_VALUE"""),19.0) -> 19 | Q20: =IFERROR(__xludf.DUMMYFUNCTION("""COMPUTED_VALUE"""),32.0) -> 32 | R20: =IFERROR(__xludf.DUMMYFUNCTION("""COMPUTED_VALUE"""),120.0) -> 120 | S20: =IFERROR(__xludf.DUMMYFUNCTION("""COMPUTED_VALUE"""),0.30833333333333335) -> 0.30833333 | T20: =IFERROR(__xludf.DUMMYFUNCTION("""COMPUTED_VALUE"""),313.1136363636364) -> 313.11364 | U20: =IFERROR(__xludf.DUMMYFUNCTION("""COMPUTED_VALUE"""),0.8409090909090909) -> 0.84090909 | V20: =IFERROR(__xludf.DUMMYFUNCTION("""COMPUTED_VALUE"""),0.4318181818181818) -> 0.43181818 | W20: =IFERROR(__xludf.DUMMYFUNCTION("""COMPUTED_VALUE"""),0.7272727272727273) -> 0.72727273 | X20: =IFERROR(__xludf.DUMMYFUNCTION("""COMPUTED_VALUE"""),2.727272727272727) -> 2.7272727 | Y20: =IFERROR(__xludf.DUMMYFUNCTION("""COMPUTED_VALUE"""),5.0) -> 5 | Z20: =IFERROR(__xludf.DUMMYFUNCTION("""COMPUTED_VALUE"""),3.0) -> 3 | AA20: =IFERROR(__xludf.DUMMYFUNCTION("""COMPUTED_VALUE"""),0.0) -> 0 | AB20: =IFERROR(__xludf.DUMMYFUNCTION("""COMPUTED_VALUE"""),3.0) -> 3 | AC20: =IFERROR(__xludf.DUMMYFUNCTION("""COMPUTED_VALUE"""),59.0) -> 59 | AD20: =IFERROR(__xludf.DUMMYFUNCTION("""COMPUTED_VALUE"""),26.0) -> 26
A21: =IFERROR(__xludf.DUMMYFUNCTION("""COMPUTED_VALUE"""),"Amateur") -> Amateur | B21: =IFERROR(__xludf.DUMMYFUNCTION("""COMPUTED_VALUE"""),"RSC002713") -> RSC002713 | C21: =IFERROR(__xludf.DUMMYFUNCTION("""COMPUTED_VALUE"""),"TimmyIU20") -> TimmyIU20 | D21: =IFERROR(__xludf.DUMMYFUNCTION("""COMPUTED_VALUE"""),"Winter Fresh Electric Eels") -> Winter Fresh Electric Eels | E21: =IFERROR(__xludf.DUMMYFUNCTION("""COMPUTED_VALUE"""),"N/A N/A") -> N/A N/A | F21: =IFERROR(__xludf.DUMMYFUNCTION("""COMPUTED_VALUE"""),53.93122557704734) -> 53.931226 | G21: =IFERROR(__xludf.DUMMYFUNCTION("""COMPUTED_VALUE"""),57.864552560707395) -> 57.864553 | H21: =IFERROR(__xludf.DUMMYFUNCTION("""COMPUTED_VALUE"""),55.89788906887737) -> 55.897889 | I21: =IFERROR(__xludf.DUMMYFUNCTION("""COMPUTED_VALUE"""),32.0) -> 32 | J21: =IFERROR(__xludf.DUMMYFUNCTION("IFERROR(FILTER(Stats!$F:$Z,(Stats!$A:$A=$A21)*(Stats!$B:$B=$B21)))"),22.0) -> 22 | K21: =IFERROR(__xludf.DUMMYFUNCTION("""COMPUTED_VALUE"""),10.0) -> 10 | L21: =IFERROR(__xludf.DUMMYFUNCTION("""COMPUTED_VALUE"""),0.6875) -> 0.6875 | M21: =IFERROR(__xludf.DUMMYFUNCTION("""COMPUTED_VALUE"""),7.0) -> 7 | N21: =IFERROR(__xludf.DUMMYFUNCTION("""COMPUTED_VALUE"""),10408.0) -> 10408 | O21: =IFERROR(__xludf.DUMMYFUNCTION("""COMPUTED_VALUE"""),30.0) -> 30 | P21: =IFERROR(__xludf.DUMMYFUNCTION("""COMPUTED_VALUE"""),11.0) -> 11 | Q21: =IFERROR(__xludf.DUMMYFUNCTION("""COMPUTED_VALUE"""),30.0) -> 30 | R21: =IFERROR(__xludf.DUMMYFUNCTION("""COMPUTED_VALUE"""),79.0) -> 79 | S21: =IFERROR(__xludf.DUMMYFUNCTION("""COMPUTED_VALUE"""),0.379746835443038) -> 0.37974684 | T21: =IFERROR(__xludf.DUMMYFUNCTION("""COMPUTED_VALUE"""),325.25) -> 325.25 | U21: =IFERROR(__xludf.DUMMYFUNCTION("""COMPUTED_VALUE"""),0.9375) -> 0.9375 | V21: =IFERROR(__xludf.DUMMYFUNCTION("""COMPUTED_VALUE"""),0.34375) -> 0.34375 | W21: =IFERROR(__xludf.DUMMYFUNCTION("""COMPUTED_VALUE"""),0.9375) -> 0.9375 | X21: =IFERROR(__xludf.DUMMYFUNCTION("""COMPUTED_VALUE"""),2.46875) -> 2.46875 | Y21: =IFERROR(__xludf.DUMMYFUNCTION("""COMPUTED_VALUE"""),3.0) -> 3 | Z21: =IFERROR(__xludf.DUMMYFUNCTION("""COMPUTED_VALUE"""),1.0) -> 1 | AA21: =IFERROR(__xludf.DUMMYFUNCTION("""COMPUTED_VALUE"""),0.0) -> 0 | AB21: =IFERROR(__xludf.DUMMYFUNCTION("""COMPUTED_VALUE"""),2.0) -> 2 | AC21: =IFERROR(__xludf.DUMMYFUNCTION("""COMPUTED_VALUE"""),15.0) -> 15 | AD21: =IFERROR(__xludf.DUMMYFUNCTION("""COMPUTED_VALUE"""),33.0) -> 33
A22: =IFERROR(__xludf.DUMMYFUNCTION("""COMPUTED_VALUE"""),"Amateur") -> Amateur | B22: =IFERROR(__xludf.DUMMYFUNCTION("""COMPUTED_VALUE"""),"RSC007581") -> RSC007581 | C22: =IFERROR(__xludf.DUMMYFUNCTION("""COMPUTED_VALUE"""),"Wrecklessjay02") -> Wrecklessjay02 | D22: =IFERROR(__xludf.DUMMYFUNCTION("""COMPUTED_VALUE"""),"Bombers") -> Bombers | E22: =IFERROR(__xludf.DUMMYFUNCTION("""COMPUTED_VALUE"""),"N/A") -> N/A | F22: =IFERROR(__xludf.DUMMYFUNCTION("""COMPUTED_VALUE"""),54.2014102094929) -> 54.20141 | G22: =IFERROR(__xludf.DUMMYFUNCTION("""COMPUTED_VALUE"""),56.90245359791163) -> 56.902454 | H22: =IFERROR(__xludf.DUMMYFUNCTION("""COMPUTED_VALUE"""),55.55193190370227) -> 55.551932 | I22: =IFERROR(__xludf.DUMMYFUNCTION("""COMPUTED_VALUE"""),47.0) -> 47 | J22: =IFERROR(__xludf.DUMMYFUNCTION("IFERROR(FILTER(Stats!$F:$Z,(Stats!$A:$A=$A22)*(Stats!$B:$B=$B22)))"),34.0) -> 34 | K22: =IFERROR(__xludf.DUMMYFUNCTION("""COMPUTED_VALUE"""),13.0) -> 13 | L22: =IFERROR(__xludf.DUMMYFUNCTION("""COMPUTED_VALUE"""),0.723404255319149) -> 0.72340426 | M22: =IFERROR(__xludf.DUMMYFUNCTION("""COMPUTED_VALUE"""),7.0) -> 7 | N22: =IFERROR(__xludf.DUMMYFUNCTION("""COMPUTED_VALUE"""),13812.0) -> 13812 | O22: =IFERROR(__xludf.DUMMYFUNCTION("""COMPUTED_VALUE"""),29.0) -> 29 | P22: =IFERROR(__xludf.DUMMYFUNCTION("""COMPUTED_VALUE"""),27.0) -> 27 | Q22: =IFERROR(__xludf.DUMMYFUNCTION("""COMPUTED_VALUE"""),40.0) -> 40 | R22: =IFERROR(__xludf.DUMMYFUNCTION("""COMPUTED_VALUE"""),106.0) -> 106 | S22: =IFERROR(__xludf.DUMMYFUNCTION("""COMPUTED_VALUE"""),0.27358490566037735) -> 0.27358491 | T22: =IFERROR(__xludf.DUMMYFUNCTION("""COMPUTED_VALUE"""),293.8723404255319) -> 293.87234 | U22: =IFERROR(__xludf.DUMMYFUNCTION("""COMPUTED_VALUE"""),0.6170212765957447) -> 0.61702128 | V22: =IFERROR(__xludf.DUMMYFUNCTION("""COMPUTED_VALUE"""),0.574468085106383) -> 0.57446809 | W22: =IFERROR(__xludf.DUMMYFUNCTION("""COMPUTED_VALUE"""),0.851063829787234) -> 0.85106383 | X22: =IFERROR(__xludf.DUMMYFUNCTION("""COMPUTED_VALUE"""),2.25531914893617) -> 2.2553191 | Y22: =IFERROR(__xludf.DUMMYFUNCTION("""COMPUTED_VALUE"""),2.0) -> 2 | Z22: =IFERROR(__xludf.DUMMYFUNCTION("""COMPUTED_VALUE"""),2.0) -> 2 | AA22: =IFERROR(__xludf.DUMMYFUNCTION("""COMPUTED_VALUE"""),1.0) -> 1 | AB22: =IFERROR(__xludf.DUMMYFUNCTION("""COMPUTED_VALUE"""),2.0) -> 2 | AC22: =IFERROR(__xludf.DUMMYFUNCTION("""COMPUTED_VALUE"""),39.0) -> 39 | AD22: =IFERROR(__xludf.DUMMYFUNCTION("""COMPUTED_VALUE"""),30.0) -> 30
A23: =IFERROR(__xludf.DUMMYFUNCTION("""COMPUTED_VALUE"""),"Amateur") -> Amateur | B23: =IFERROR(__xludf.DUMMYFUNCTION("""COMPUTED_VALUE"""),"RSC006375") -> RSC006375 | C23: =IFERROR(__xludf.DUMMYFUNCTION("""COMPUTED_VALUE"""),"Rich-Rollin6060") -> Rich-Rollin6060 | D23: =IFERROR(__xludf.DUMMYFUNCTION("""COMPUTED_VALUE"""),"Garlic Knots") -> Garlic Knots | E23: =IFERROR(__xludf.DUMMYFUNCTION("""COMPUTED_VALUE"""),"N/A") -> N/A | F23: =IFERROR(__xludf.DUMMYFUNCTION("""COMPUTED_VALUE"""),54.59217446996295) -> 54.592174 | G23: =IFERROR(__xludf.DUMMYFUNCTION("""COMPUTED_VALUE"""),55.72317975002479) -> 55.72318 | H23: =IFERROR(__xludf.DUMMYFUNCTION("""COMPUTED_VALUE"""),55.15767710999387) -> 55.157677 | I23: =IFERROR(__xludf.DUMMYFUNCTION("""COMPUTED_VALUE"""),42.0) -> 42 | J23: =IFERROR(__xludf.DUMMYFUNCTION("IFERROR(FILTER(Stats!$F:$Z,(Stats!$A:$A=$A23)*(Stats!$B:$B=$B23)))"),23.0) -> 23 | K23: =IFERROR(__xludf.DUMMYFUNCTION("""COMPUTED_VALUE"""),19.0) -> 19 | L23: =IFERROR(__xludf.DUMMYFUNCTION("""COMPUTED_VALUE"""),0.5476190476190477) -> 0.54761905 | M23: =IFERROR(__xludf.DUMMYFUNCTION("""COMPUTED_VALUE"""),4.0) -> 4 | N23: =IFERROR(__xludf.DUMMYFUNCTION("""COMPUTED_VALUE"""),11869.0) -> 11869 | O23: =IFERROR(__xludf.DUMMYFUNCTION("""COMPUTED_VALUE"""),33.0) -> 33 | P23: =IFERROR(__xludf.DUMMYFUNCTION("""COMPUTED_VALUE"""),22.0) -> 22 | Q23: =IFERROR(__xludf.DUMMYFUNCTION("""COMPUTED_VALUE"""),17.0) -> 17 | R23: =IFERROR(__xludf.DUMMYFUNCTION("""COMPUTED_VALUE"""),101.0) -> 101 | S23: =IFERROR(__xludf.DUMMYFUNCTION("""COMPUTED_VALUE"""),0.32673267326732675) -> 0.32673267 | T23: =IFERROR(__xludf.DUMMYFUNCTION("""COMPUTED_VALUE"""),282.5952380952381) -> 282.59524 | U23: =IFERROR(__xludf.DUMMYFUNCTION("""COMPUTED_VALUE"""),0.7857142857142857) -> 0.78571429 | V23: =IFERROR(__xludf.DUMMYFUNCTION("""COMPUTED_VALUE"""),0.5238095238095238) -> 0.52380952 | W23: =IFERROR(__xludf.DUMMYFUNCTION("""COMPUTED_VALUE"""),0.40476190476190477) -> 0.4047619 | X23: =IFERROR(__xludf.DUMMYFUNCTION("""COMPUTED_VALUE"""),2.4047619047619047) -> 2.4047619 | Y23: =IFERROR(__xludf.DUMMYFUNCTION("""COMPUTED_VALUE"""),4.0) -> 4 | Z23: =IFERROR(__xludf.DUMMYFUNCTION("""COMPUTED_VALUE"""),2.0) -> 2 | AA23: =IFERROR(__xludf.DUMMYFUNCTION("""COMPUTED_VALUE"""),0.0) -> 0 | AB23: =IFERROR(__xludf.DUMMYFUNCTION("""COMPUTED_VALUE"""),0.0) -> 0 | AC23: =IFERROR(__xludf.DUMMYFUNCTION("""COMPUTED_VALUE"""),54.0) -> 54 | AD23: =IFERROR(__xludf.DUMMYFUNCTION("""COMPUTED_VALUE"""),41.0) -> 41
A24: =IFERROR(__xludf.DUMMYFUNCTION("""COMPUTED_VALUE"""),"Amateur") -> Amateur | B24: =IFERROR(__xludf.DUMMYFUNCTION("""COMPUTED_VALUE"""),"RSC007161") -> RSC007161 | C24: =IFERROR(__xludf.DUMMYFUNCTION("""COMPUTED_VALUE"""),"MrAnderpants") -> MrAnderpants | D24: =IFERROR(__xludf.DUMMYFUNCTION("""COMPUTED_VALUE"""),"Winter Fresh Electric Eels Garlic Knots") -> Winter Fresh Electric Eels Garlic Knots | E24: =IFERROR(__xludf.DUMMYFUNCTION("""COMPUTED_VALUE"""),"N/A N/A N/A") -> N/A N/A N/A | F24: =IFERROR(__xludf.DUMMYFUNCTION("""COMPUTED_VALUE"""),58.43703465921884) -> 58.437035 | G24: =IFERROR(__xludf.DUMMYFUNCTION("""COMPUTED_VALUE"""),48.72013659312971) -> 48.720137 | H24: =IFERROR(__xludf.DUMMYFUNCTION("""COMPUTED_VALUE"""),53.578585626174274) -> 53.578586 | I24: =IFERROR(__xludf.DUMMYFUNCTION("""COMPUTED_VALUE"""),11.0) -> 11 | J24: =IFERROR(__xludf.DUMMYFUNCTION("IFERROR(FILTER(Stats!$F:$Z,(Stats!$A:$A=$A24)*(Stats!$B:$B=$B24)))"),5.0) -> 5 | K24: =IFERROR(__xludf.DUMMYFUNCTION("""COMPUTED_VALUE"""),6.0) -> 6 | L24: =IFERROR(__xludf.DUMMYFUNCTION("""COMPUTED_VALUE"""),0.45454545454545453) -> 0.45454545 | M24: =IFERROR(__xludf.DUMMYFUNCTION("""COMPUTED_VALUE"""),2.0) -> 2 | N24: =IFERROR(__xludf.DUMMYFUNCTION("""COMPUTED_VALUE"""),3510.0) -> 3510 | O24: =IFERROR(__xludf.DUMMYFUNCTION("""COMPUTED_VALUE"""),11.0) -> 11 | P24: =IFERROR(__xludf.DUMMYFUNCTION("""COMPUTED_VALUE"""),4.0) -> 4 | Q24: =IFERROR(__xludf.DUMMYFUNCTION("""COMPUTED_VALUE"""),11.0) -> 11 | R24: =IFERROR(__xludf.DUMMYFUNCTION("""COMPUTED_VALUE"""),22.0) -> 22 | S24: =IFERROR(__xludf.DUMMYFUNCTION("""COMPUTED_VALUE"""),0.5) -> 0.5 | T24: =IFERROR(__xludf.DUMMYFUNCTION("""COMPUTED_VALUE"""),319.09090909090907) -> 319.09091 | U24: =IFERROR(__xludf.DUMMYFUNCTION("""COMPUTED_VALUE"""),1.0) -> 1 | V24: =IFERROR(__xludf.DUMMYFUNCTION("""COMPUTED_VALUE"""),0.36363636363636365) -> 0.36363636 | W24: =IFERROR(__xludf.DUMMYFUNCTION("""COMPUTED_VALUE"""),1.0) -> 1 | X24: =IFERROR(__xludf.DUMMYFUNCTION("""COMPUTED_VALUE"""),2.0) -> 2 | Y24: =IFERROR(__xludf.DUMMYFUNCTION("""COMPUTED_VALUE"""),0.0) -> 0 | Z24: =IFERROR(__xludf.DUMMYFUNCTION("""COMPUTED_VALUE"""),0.0) -> 0 | AA24: =IFERROR(__xludf.DUMMYFUNCTION("""COMPUTED_VALUE"""),0.0) -> 0 | AB24: =IFERROR(__xludf.DUMMYFUNCTION("""COMPUTED_VALUE"""),0.0) -> 0 | AC24: =IFERROR(__xludf.DUMMYFUNCTION("""COMPUTED_VALUE"""),14.0) -> 14 | AD24: =IFERROR(__xludf.DUMMYFUNCTION("""COMPUTED_VALUE"""),9.0) -> 9
A25: =IFERROR(__xludf.DUMMYFUNCTION("""COMPUTED_VALUE"""),"Amateur") -> Amateur | B25: =IFERROR(__xludf.DUMMYFUNCTION("""COMPUTED_VALUE"""),"RSC000654") -> RSC000654 | C25: =IFERROR(__xludf.DUMMYFUNCTION("""COMPUTED_VALUE"""),"Rocci") -> Rocci | D25: =IFERROR(__xludf.DUMMYFUNCTION("""COMPUTED_VALUE"""),"Electric Eels") -> Electric Eels | E25: =IFERROR(__xludf.DUMMYFUNCTION("""COMPUTED_VALUE"""),"N/A") -> N/A | F25: =IFERROR(__xludf.DUMMYFUNCTION("""COMPUTED_VALUE"""),67.97782190763397) -> 67.977822 | G25: =IFERROR(__xludf.DUMMYFUNCTION("""COMPUTED_VALUE"""),38.4757798476672) -> 38.47578 | H25: =IFERROR(__xludf.DUMMYFUNCTION("""COMPUTED_VALUE"""),53.22680087765058) -> 53.226801 | I25: =IFERROR(__xludf.DUMMYFUNCTION("""COMPUTED_VALUE"""),4.0) -> 4 | J25: =IFERROR(__xludf.DUMMYFUNCTION("IFERROR(FILTER(Stats!$F:$Z,(Stats!$A:$A=$A25)*(Stats!$B:$B=$B25)))"),2.0) -> 2 | K25: =IFERROR(__xludf.DUMMYFUNCTION("""COMPUTED_VALUE"""),2.0) -> 2 | L25: =IFERROR(__xludf.DUMMYFUNCTION("""COMPUTED_VALUE"""),0.5) -> 0.5 | M25: =IFERROR(__xludf.DUMMYFUNCTION("""COMPUTED_VALUE"""),2.0) -> 2 | N25: =IFERROR(__xludf.DUMMYFUNCTION("""COMPUTED_VALUE"""),1118.0) -> 1118 | O25: =IFERROR(__xludf.DUMMYFUNCTION("""COMPUTED_VALUE"""),2.0) -> 2 | P25: =IFERROR(__xludf.DUMMYFUNCTION("""COMPUTED_VALUE"""),1.0) -> 1 | Q25: =IFERROR(__xludf.DUMMYFUNCTION("""COMPUTED_VALUE"""),6.0) -> 6 | R25: =IFERROR(__xludf.DUMMYFUNCTION("""COMPUTED_VALUE"""),5.0) -> 5 | S25: =IFERROR(__xludf.DUMMYFUNCTION("""COMPUTED_VALUE"""),0.4) -> 0.4 | T25: =IFERROR(__xludf.DUMMYFUNCTION("""COMPUTED_VALUE"""),279.5) -> 279.5 | U25: =IFERROR(__xludf.DUMMYFUNCTION("""COMPUTED_VALUE"""),0.5) -> 0.5 | V25: =IFERROR(__xludf.DUMMYFUNCTION("""COMPUTED_VALUE"""),0.25) -> 0.25 | W25: =IFERROR(__xludf.DUMMYFUNCTION("""COMPUTED_VALUE"""),1.5) -> 1.5 | X25: =IFERROR(__xludf.DUMMYFUNCTION("""COMPUTED_VALUE"""),1.25) -> 1.25 | Y25: =IFERROR(__xludf.DUMMYFUNCTION("""COMPUTED_VALUE"""),1.0) -> 1 | Z25: =IFERROR(__xludf.DUMMYFUNCTION("""COMPUTED_VALUE"""),0.0) -> 0 | AA25: =IFERROR(__xludf.DUMMYFUNCTION("""COMPUTED_VALUE"""),0.0) -> 0 | AB25: =IFERROR(__xludf.DUMMYFUNCTION("""COMPUTED_VALUE"""),1.0) -> 1 | AC25: =IFERROR(__xludf.DUMMYFUNCTION("""COMPUTED_VALUE"""),1.0) -> 1 | AD25: =IFERROR(__xludf.DUMMYFUNCTION("""COMPUTED_VALUE"""),0.0) -> 0
A26: =IFERROR(__xludf.DUMMYFUNCTION("""COMPUTED_VALUE"""),"Amateur") -> Amateur | B26: =IFERROR(__xludf.DUMMYFUNCTION("""COMPUTED_VALUE"""),"RSC008327") -> RSC008327 | C26: =IFERROR(__xludf.DUMMYFUNCTION("""COMPUTED_VALUE"""),"tempo_rl_ttv") -> tempo_rl_ttv | D26: =IFERROR(__xludf.DUMMYFUNCTION("""COMPUTED_VALUE"""),"Winter Fresh") -> Winter Fresh | E26: =IFERROR(__xludf.DUMMYFUNCTION("""COMPUTED_VALUE"""),"N/A") -> N/A | F26: =IFERROR(__xludf.DUMMYFUNCTION("""COMPUTED_VALUE"""),52.18672684751736) -> 52.186727 | G26: =IFERROR(__xludf.DUMMYFUNCTION("""COMPUTED_VALUE"""),52.56746177606754) -> 52.567462 | H26: =IFERROR(__xludf.DUMMYFUNCTION("""COMPUTED_VALUE"""),52.37709431179245) -> 52.377094 | I26: =IFERROR(__xludf.DUMMYFUNCTION("""COMPUTED_VALUE"""),36.0) -> 36 | J26: =IFERROR(__xludf.DUMMYFUNCTION("IFERROR(FILTER(Stats!$F:$Z,(Stats!$A:$A=$A26)*(Stats!$B:$B=$B26)))"),22.0) -> 22 | K26: =IFERROR(__xludf.DUMMYFUNCTION("""COMPUTED_VALUE"""),14.0) -> 14 | L26: =IFERROR(__xludf.DUMMYFUNCTION("""COMPUTED_VALUE"""),0.6111111111111112) -> 0.61111111 | M26: =IFERROR(__xludf.DUMMYFUNCTION("""COMPUTED_VALUE"""),9.0) -> 9 | N26: =IFERROR(__xludf.DUMMYFUNCTION("""COMPUTED_VALUE"""),10858.0) -> 10858 | O26: =IFERROR(__xludf.DUMMYFUNCTION("""COMPUTED_VALUE"""),28.0) -> 28 | P26: =IFERROR(__xludf.DUMMYFUNCTION("""COMPUTED_VALUE"""),14.0) -> 14 | Q26: =IFERROR(__xludf.DUMMYFUNCTION("""COMPUTED_VALUE"""),32.0) -> 32 | R26: =IFERROR(__xludf.DUMMYFUNCTION("""COMPUTED_VALUE"""),75.0) -> 75 | S26: =IFERROR(__xludf.DUMMYFUNCTION("""COMPUTED_VALUE"""),0.37333333333333335) -> 0.37333333 | T26: =IFERROR(__xludf.DUMMYFUNCTION("""COMPUTED_VALUE"""),301.6111111111111) -> 301.61111 | U26: =IFERROR(__xludf.DUMMYFUNCTION("""COMPUTED_VALUE"""),0.7777777777777778) -> 0.77777778 | V26: =IFERROR(__xludf.DUMMYFUNCTION("""COMPUTED_VALUE"""),0.3888888888888889) -> 0.38888889 | W26: =IFERROR(__xludf.DUMMYFUNCTION("""COMPUTED_VALUE"""),0.8888888888888888) -> 0.88888889 | X26: =IFERROR(__xludf.DUMMYFUNCTION("""COMPUTED_VALUE"""),2.0833333333333335) -> 2.0833333 | Y26: =IFERROR(__xludf.DUMMYFUNCTION("""COMPUTED_VALUE"""),5.0) -> 5 | Z26: =IFERROR(__xludf.DUMMYFUNCTION("""COMPUTED_VALUE"""),2.0) -> 2 | AA26: =IFERROR(__xludf.DUMMYFUNCTION("""COMPUTED_VALUE"""),0.0) -> 0 | AB26: =IFERROR(__xludf.DUMMYFUNCTION("""COMPUTED_VALUE"""),4.0) -> 4 | AC26: =IFERROR(__xludf.DUMMYFUNCTION("""COMPUTED_VALUE"""),51.0) -> 51 | AD26: =IFERROR(__xludf.DUMMYFUNCTION("""COMPUTED_VALUE"""),24.0) -> 24
A27: =IFERROR(__xludf.DUMMYFUNCTION("""COMPUTED_VALUE"""),"Amateur") -> Amateur | B27: =IFERROR(__xludf.DUMMYFUNCTION("""COMPUTED_VALUE"""),"RSC008130") -> RSC008130 | C27: =IFERROR(__xludf.DUMMYFUNCTION("""COMPUTED_VALUE"""),"BeardedFrodo1") -> BeardedFrodo1 | D27: =IFERROR(__xludf.DUMMYFUNCTION("""COMPUTED_VALUE"""),"Bombers") -> Bombers | E27: =IFERROR(__xludf.DUMMYFUNCTION("""COMPUTED_VALUE"""),"N/A") -> N/A | F27: =IFERROR(__xludf.DUMMYFUNCTION("""COMPUTED_VALUE"""),48.96800980931988) -> 48.96801 | G27: =IFERROR(__xludf.DUMMYFUNCTION("""COMPUTED_VALUE"""),55.56976004363583) -> 55.56976 | H27: =IFERROR(__xludf.DUMMYFUNCTION("""COMPUTED_VALUE"""),52.26888492647785) -> 52.268885 | I27: =IFERROR(__xludf.DUMMYFUNCTION("""COMPUTED_VALUE"""),55.0) -> 55 | J27: =IFERROR(__xludf.DUMMYFUNCTION("IFERROR(FILTER(Stats!$F:$Z,(Stats!$A:$A=$A27)*(Stats!$B:$B=$B27)))"),38.0) -> 38 | K27: =IFERROR(__xludf.DUMMYFUNCTION("""COMPUTED_VALUE"""),17.0) -> 17 | L27: =IFERROR(__xludf.DUMMYFUNCTION("""COMPUTED_VALUE"""),0.6909090909090909) -> 0.69090909 | M27: =IFERROR(__xludf.DUMMYFUNCTION("""COMPUTED_VALUE"""),13.0) -> 13 | N27: =IFERROR(__xludf.DUMMYFUNCTION("""COMPUTED_VALUE"""),16424.0) -> 16424 | O27: =IFERROR(__xludf.DUMMYFUNCTION("""COMPUTED_VALUE"""),44.0) -> 44 | P27: =IFERROR(__xludf.DUMMYFUNCTION("""COMPUTED_VALUE"""),23.0) -> 23 | Q27: =IFERROR(__xludf.DUMMYFUNCTION("""COMPUTED_VALUE"""),51.0) -> 51 | R27: =IFERROR(__xludf.DUMMYFUNCTION("""COMPUTED_VALUE"""),124.0) -> 124 | S27: =IFERROR(__xludf.DUMMYFUNCTION("""COMPUTED_VALUE"""),0.3548387096774194) -> 0.35483871 | T27: =IFERROR(__xludf.DUMMYFUNCTION("""COMPUTED_VALUE"""),298.6181818181818) -> 298.61818 | U27: =IFERROR(__xludf.DUMMYFUNCTION("""COMPUTED_VALUE"""),0.8) -> 0.8 | V27: =IFERROR(__xludf.DUMMYFUNCTION("""COMPUTED_VALUE"""),0.41818181818181815) -> 0.41818182 | W27: =IFERROR(__xludf.DUMMYFUNCTION("""COMPUTED_VALUE"""),0.9272727272727272) -> 0.92727273 | X27: =IFERROR(__xludf.DUMMYFUNCTION("""COMPUTED_VALUE"""),2.2545454545454544) -> 2.2545455 | Y27: =IFERROR(__xludf.DUMMYFUNCTION("""COMPUTED_VALUE"""),5.0) -> 5 | Z27: =IFERROR(__xludf.DUMMYFUNCTION("""COMPUTED_VALUE"""),2.0) -> 2 | AA27: =IFERROR(__xludf.DUMMYFUNCTION("""COMPUTED_VALUE"""),1.0) -> 1 | AB27: =IFERROR(__xludf.DUMMYFUNCTION("""COMPUTED_VALUE"""),1.0) -> 1 | AC27: =IFERROR(__xludf.DUMMYFUNCTION("""COMPUTED_VALUE"""),27.0) -> 27 | AD27: =IFERROR(__xludf.DUMMYFUNCTION("""COMPUTED_VALUE"""),36.0) -> 36
